<?xml version="1.0"?>
<robot name="scara">
    <link name="world" />

    <link name="base_link">
        <visual>
            <geometry>
                <box size="0.09 0.09 0.11" />
            </geometry>
            <origin rpy="0 0 0" xyz="0 0 0.055" />
        </visual>
        <collision>
            <geometry>
                <box size="0.09 0.09 0.11" />
            </geometry>
            <origin rpy="0 0 0" xyz="0 0 0.055" />
        </collision>
        <inertial>
            <mass value="0.333" /> <!-- 0.196 metal + 0.138 motor (2) -->
            <inertia ixx="0.0056055" iyy="0.0056055" izz="0.00044955" />
        </inertial>
    </link>

    <link name="virtual1">
    <visual>
            <geometry>
                <box size="0.04 0.04 0.015" />
            </geometry>
            <origin rpy="0 0 0" xyz="0 0 0.0075" />
        </visual>
        <collision>
            <geometry>
                <box size="0.04 0.04 0.015" />
            </geometry>
            <origin rpy="0 0 0" xyz="0 0 0.0075" />
        </collision>
        <inertial>
            <mass value="0.333" /> <!-- 0.196 metal + 0.138 motor (2) -->
            <inertia ixx="0.0056055" iyy="0.0056055" izz="0.00044955" />
        </inertial>
    </link>

    <link name="l1">
        <visual>
            <geometry>
                <box size="0.13 0.025 0.057" />
            </geometry>
            <origin rpy="0.0 0 0" xyz="0.065 0 0" />
        </visual>
        <collision>
            <geometry>
                <box size="0.13 0.025 0.057" />
            </geometry>
            <origin rpy="0.00 0 0" xyz="0.065 0 0" />
        </collision>
        <inertial>
            <mass value="0.042" /> <!-- 0.042 metal + 0.069 motor  -->
            <inertia ixx="0.0003228" iyy="0.001679" izz="0.00146" />
        </inertial>
    </link>

    <link name="l2">
        <visual>
            <geometry>
                <box size="0.13 0.025 0.057" />
            </geometry>
            <origin rpy="0 0 0" xyz="0.065 0 0" />
        </visual>
        <collision>
            <geometry>
                <box size="0.13 0.025 0.057" />
            </geometry>
            <origin rpy="0 0 0" xyz="0.065 0 0" />
        </collision>
        <inertial>
            <mass value="0.165" /> <!-- 0.096 metal + 0.069 motor  -->
            <inertia ixx="0.0003228" iyy="0.001679" izz="0.00146" />
        </inertial>
    </link>

    <link name="l3">
        <visual>
            <geometry>
                <box size="0.08 0.05 0.057" />
            </geometry>
            <origin rpy="0 0 0" xyz="0.02 -0.0125 0" />
        </visual>
        <collision>
            <geometry>
                <box size="0.08 0.05 0.057" />
            </geometry>
            <origin rpy="0 0 0" xyz="0.02 -0.0125 0" />
        </collision>
        <inertial>
            <mass value="0.168" /> <!-- 0.030 metal + 0.138 motor (2)  -->
            <inertia ixx="0.0004791" iyy="0.0008041" izz="0.0007417" />
        </inertial>
    </link>

    <link name="virtual2">
    </link>

    <link name="end_effector">
        <visual>
            <geometry>
                <cylinder radius="0.01" length="0.01" />
            </geometry>
            <origin rpy="0 0 0" xyz="0.0 0.0 0.005" />
        </visual>
        <collision>
            <geometry>
                <cylinder radius="0.01" length="0.01" />
            </geometry>
            <origin rpy="0 0 0" xyz="0.0 0.0 0.005" />
        </collision>
        <inertial>
            <mass value="0.01" /> <!-- 0.030 metal + 0.138 motor (2)  -->
            <inertia ixx="0.0004791" iyy="0.0008041" izz="0.0007417" />
        </inertial>
    </link>

    <joint name="ref" type="fixed">
        <parent link="world" />
        <child link="base_link" />
    </joint>

    <joint name="theta1" type="revolute">
        <axis xyz="0 0 1" />
        <parent link="base_link" />
        <child link="virtual1" />
        <origin rpy="0 0 0" xyz="0 0 0.11" />
        <limit lower="-90" upper="90" effort="20" velocity="1.0472" />
    </joint>

    <joint name="theta2" type="revolute">
        <axis xyz="0 0 1" />
        <parent link="virtual1" />
        <child link="l1" />
        <origin rpy="0 -1.570796 -1.570796" xyz="0 0 0" />
        <limit lower="-90" upper="90" effort="20" velocity="1.0472" />
    </joint>

    <joint name="theta3" type="revolute">
        <axis xyz="0 0 1" />
        <parent link="l1" />
        <child link="l2" />
        <origin rpy="0 0 1.570796" xyz="0.115 0 0" />
        <limit lower="-90" upper="90" effort="20" velocity="1.0472" />
    </joint>

    <joint name="theta4" type="revolute">
        <axis xyz="0 0 1" />
        <parent link="l2" />
        <child link="l3" />
        <origin rpy="0 0 0" xyz="0.115 0 0" />
        <limit lower="-90" upper="90" effort="20" velocity="1.0472" />
    </joint>

    <joint name="v_joint1" type="fixed">
        <axis xyz="0 0 1" />
        <parent link="l3" />
        <child link="virtual2" />
        <origin rpy="1.570796 0 1.570796" xyz="0.06 -0.0275 0" />
    </joint>

    <joint name="theta5" type="revolute">
        <axis xyz="0 0 1" />
        <parent link="virtual2" />
        <child link="end_effector" />
        <origin rpy="0 0 0" xyz="0 0 0" />
        <limit lower="-90" upper="90" effort="20" velocity="1.0472" />
    </joint>
    
</robot>